Workbook
Name _\z: #REF!
Name __________________________________________________________________________________________pas10: #REF!
Name __________________________________________________________________________________________pas200: #REF!
Name __________________________________________________________________________________________pas40: #REF!
Name ________________________________________________________________________________________pas10: #REF!
Name ________________________________________________________________________________________pas200: #REF!
Name ________________________________________________________________________________________pas40: #REF!
Name ______________________________________________________________________________________pas10: #REF!
Name ______________________________________________________________________________________pas200: #REF!
Name ______________________________________________________________________________________pas40: #REF!
Name _____________________________________________________________________________________pas10: #REF!
Name _____________________________________________________________________________________pas200: #REF!
Name _____________________________________________________________________________________pas40: #REF!
Name ____________________________________________________________________________________pas10: #REF!
Name ____________________________________________________________________________________pas200: #REF!
Name ____________________________________________________________________________________pas40: #REF!
Name __________________________________________________________________________________pas10: #REF!
Name __________________________________________________________________________________pas200: #REF!
Name __________________________________________________________________________________pas40: #REF!
Name _________________________________________________________________________________pas10: #REF!
Name _________________________________________________________________________________pas200: #REF!
Name _________________________________________________________________________________pas40: #REF!
Name ________________________________________________________________________________pas10: #REF!
Name ________________________________________________________________________________pas200: #REF!
Name ________________________________________________________________________________pas40: #REF!
Name ________________________________________________________________________________Rbv1: #REF!
Name _______________________________________________________________________________pas10: #REF!
Name _______________________________________________________________________________pas200: #REF!
Name _______________________________________________________________________________pas40: #REF!
Name _______________________________________________________________________________Rbv1: #REF!
Name ______________________________________________________________________________bri1: #REF!
Name ______________________________________________________________________________bri2: #REF!
Name ______________________________________________________________________________drb1: #REF!
Name ______________________________________________________________________________drb2: #REF!
Name ______________________________________________________________________________mat02: #REF!
Name ______________________________________________________________________________mat03: #REF!
Name ______________________________________________________________________________mat04: #REF!
Name ______________________________________________________________________________mat05: #REF!
Name ______________________________________________________________________________mat06: #REF!
Name ______________________________________________________________________________pas10: #REF!
Name ______________________________________________________________________________pas200: #REF!
Name ______________________________________________________________________________pas40: #REF!
Name ______________________________________________________________________________pen01: #REF!
Name ______________________________________________________________________________pen02: #REF!
Name ______________________________________________________________________________pen03: #REF!
Name ______________________________________________________________________________pen04: #REF!
Name ______________________________________________________________________________pen06: #REF!
Name ______________________________________________________________________________pen07: #REF!
Name ______________________________________________________________________________pen08: #REF!
Name ______________________________________________________________________________pen09: #REF!
Name ______________________________________________________________________________pen10: #REF!
Name ______________________________________________________________________________pen40: #REF!
Name ______________________________________________________________________________Rbv1: #REF!
Name _____________________________________________________________________________bri1: #REF!
Name _____________________________________________________________________________bri2: #REF!
Name _____________________________________________________________________________drb1: #REF!
Name _____________________________________________________________________________drb2: #REF!
Name _____________________________________________________________________________mat01: #REF!
Name _____________________________________________________________________________mat02: #REF!
Name _____________________________________________________________________________mat03: #REF!

Sheet Equipe Técnica Exec.
C8: Executante: | D8: CONSÓRCIO RODOVIA PR 317 IGUARAÇU MARINGÁ | J8: Contrato: | K8: 141 / 2025
C9: Rodovia: | D9: PR-317 | J9: Relatório Nº: | K9: 13
C10: Trecho: | D10: DUPLICAÇÃO E RESTAURAÇÃO DA PISTA EXISTENTE DA RODOVIA PR-317, TRECHO IGUARAÇU–MARINGÁ | J10: Período de Referência: | K10: 46235
C12: N.° | D12: Nome | H12: Função
C14: 1 | D14: =IFERROR(VLOOKUP($C14,efetivo!$A:$C,2,FALSE),"") -> DANIEL DRAGO SANTANA | H14: =IFERROR(VLOOKUP($C14,efetivo!$A:$C,3,FALSE),"") -> AJUDANTE GERAL
C15: =C14+1 -> 2 | D15: =IFERROR(VLOOKUP($C15,efetivo!$A:$C,2,FALSE),"") -> GUILHERME BREGUES DOS SANTOS | H15: =IFERROR(VLOOKUP($C15,efetivo!$A:$C,3,FALSE),"") -> AJUDANTE GERAL
C16: =C15+1 -> 3 | D16: =IFERROR(VLOOKUP($C16,efetivo!$A:$C,2,FALSE),"") -> LEONE JOAO RAIMUNDO | H16: =IFERROR(VLOOKUP($C16,efetivo!$A:$C,3,FALSE),"") -> AJUDANTE GERAL
C17: =C16+1 -> 4 | D17: =IFERROR(VLOOKUP($C17,efetivo!$A:$C,2,FALSE),"") -> ROBENILTON ALVES DOS SANTOS | H17: =IFERROR(VLOOKUP($C17,efetivo!$A:$C,3,FALSE),"") -> AJUDANTE GERAL
C18: =C17+1 -> 5 | D18: =IFERROR(VLOOKUP($C18,efetivo!$A:$C,2,FALSE),"") -> RODOLFO LUIZ DA ROCHA | H18: =IFERROR(VLOOKUP($C18,efetivo!$A:$C,3,FALSE),"") -> AJUDANTE GERAL
C19: =C18+1 -> 6 | D19: =IFERROR(VLOOKUP($C19,efetivo!$A:$C,2,FALSE),"") -> SIDNEI APARECIDO PEREIRA | H19: =IFERROR(VLOOKUP($C19,efetivo!$A:$C,3,FALSE),"") -> AJUDANTE GERAL
C20: =C19+1 -> 7 | D20: =IFERROR(VLOOKUP($C20,efetivo!$A:$C,2,FALSE),"") -> CLEITON MIGUEL DA CUNHA | H20: =IFERROR(VLOOKUP($C20,efetivo!$A:$C,3,FALSE),"") -> AJUDANTE GERAL
C21: =C20+1 -> 8 | D21: =IFERROR(VLOOKUP($C21,efetivo!$A:$C,2,FALSE),"") -> JESUINO GERALDO DOS ANJOS | H21: =IFERROR(VLOOKUP($C21,efetivo!$A:$C,3,FALSE),"") -> AJUDANTE GERAL
C22: =C21+1 -> 9 | D22: =IFERROR(VLOOKUP($C22,efetivo!$A:$C,2,FALSE),"") -> KAIQUE APARECIDO CUNHA HONORATO | H22: =IFERROR(VLOOKUP($C22,efetivo!$A:$C,3,FALSE),"") -> AJUDANTE GERAL
C23: =C22+1 -> 10 | D23: =IFERROR(VLOOKUP($C23,efetivo!$A:$C,2,FALSE),"") -> LEONARDO MOTA | H23: =IFERROR(VLOOKUP($C23,efetivo!$A:$C,3,FALSE),"") -> AJUDANTE GERAL
C24: =C23+1 -> 11 | D24: =IFERROR(VLOOKUP($C24,efetivo!$A:$C,2,FALSE),"") -> EVONIO CRISTIANO RODRIGUES FERREIRA | H24: =IFERROR(VLOOKUP($C24,efetivo!$A:$C,3,FALSE),"") -> AJUDANTE GERAL
C25: =C24+1 -> 12 | D25: =IFERROR(VLOOKUP($C25,efetivo!$A:$C,2,FALSE),"") -> JANDERSON CESAR PEREIRA ; | H25: =IFERROR(VLOOKUP($C25,efetivo!$A:$C,3,FALSE),"") -> AJUDANTE GERAL
C26: =C25+1 -> 13 | D26: =IFERROR(VLOOKUP($C26,efetivo!$A:$C,2,FALSE),"") -> DAVI DE JESUS LEAL | H26: =IFERROR(VLOOKUP($C26,efetivo!$A:$C,3,FALSE),"") -> AJUDANTE GERAL
... C56: =C55+1 -> 43 | D56: =IFERROR(VLOOKUP($C56,efetivo!$A:$C,2,FALSE),"") -> JAILSON TENORIO DA SILVA | H56: =IFERROR(VLOOKUP($C56,efetivo!$A:$C,3,FALSE),"") -> ARMADOR
C70: Executante: | D70: CONSÓRCIO RODOVIA PR 317 IGUARAÇU MARINGÁ | J70: Contrato: | K70: 141 / 2025
C71: Rodovia: | D71: PR-317 | J71: Relatório Nº: | K71: 13
C72: Trecho: | D72: DUPLICAÇÃO E RESTAURAÇÃO DA PISTA EXISTENTE DA RODOVIA PR-317, TRECHO IGUARAÇU–MARINGÁ | J72: Período de Referência: | K72: 46235
C74: N.° | D74: Nome | H74: Função
C76: =C56+1 -> 44 | D76: =IFERROR(VLOOKUP($C76,efetivo!$A:$C,2,FALSE),"") -> ROGERIO NUNES DE OLIVEIRA | H76: =IFERROR(VLOOKUP($C76,efetivo!$A:$C,3,FALSE),"") -> ARMADOR
C77: =C76+1 -> 45 | D77: =IFERROR(VLOOKUP($C77,efetivo!$A:$C,2,FALSE),"") -> JOSE FRANCISCO DOS SANTOS | H77: =IFERROR(VLOOKUP($C77,efetivo!$A:$C,3,FALSE),"") -> ARMADOR
C78: =C77+1 -> 46 | D78: =IFERROR(VLOOKUP($C78,efetivo!$A:$C,2,FALSE),"") -> WASHGTON ANTUNES DE OLIVEIRA | H78: =IFERROR(VLOOKUP($C78,efetivo!$A:$C,3,FALSE),"") -> ARMADOR
C79: =C78+1 -> 47 | D79: =IFERROR(VLOOKUP($C79,efetivo!$A:$C,2,FALSE),"") -> ISMAEL APARECIDO NOGUEIRA | H79: =IFERROR(VLOOKUP($C79,efetivo!$A:$C,3,FALSE),"") -> AUXILIAR DE LABORATÓRIO I
C80: =C79+1 -> 48 | D80: =IFERROR(VLOOKUP($C80,efetivo!$A:$C,2,FALSE),"") -> JOSE CARLOS ROSALINO | H80: =IFERROR(VLOOKUP($C80,efetivo!$A:$C,3,FALSE),"") -> CALDERISTA
C81: =C80+1 -> 49 | D81: =IFERROR(VLOOKUP($C81,efetivo!$A:$C,2,FALSE),"") -> NATALICIO DA SILVA AGUIAR | H81: =IFERROR(VLOOKUP($C81,efetivo!$A:$C,3,FALSE),"") -> CALDERISTA
C82: =C81+1 -> 50 | D82: =IFERROR(VLOOKUP($C82,efetivo!$A:$C,2,FALSE),"") -> AFONSO MORETTI SANCHEZ | H82: =IFERROR(VLOOKUP($C82,efetivo!$A:$C,3,FALSE),"") -> CARPINTEIRO
C83: =C82+1 -> 51 | D83: =IFERROR(VLOOKUP($C83,efetivo!$A:$C,2,FALSE),"") -> ADENILTON BARRETO DE SOUZA | H83: =IFERROR(VLOOKUP($C83,efetivo!$A:$C,3,FALSE),"") -> CARPINTEIRO
C84: =C83+1 -> 52 | D84: =IFERROR(VLOOKUP($C84,efetivo!$A:$C,2,FALSE),"") -> EZEQUIEL DA BOAVENTURA | H84: =IFERROR(VLOOKUP($C84,efetivo!$A:$C,3,FALSE),"") -> CARPINTEIRO
C85: =C84+1 -> 53 | D85: =IFERROR(VLOOKUP($C85,efetivo!$A:$C,2,FALSE),"") -> FERNANDO AUGUSTO MIRA DOS SANTOS | H85: =IFERROR(VLOOKUP($C85,efetivo!$A:$C,3,FALSE),"") -> CARPINTEIRO
C86: =C85+1 -> 54 | D86: =IFERROR(VLOOKUP($C86,efetivo!$A:$C,2,FALSE),"") -> JOSE NILTON APARECIDO HONORATO | H86: =IFERROR(VLOOKUP($C86,efetivo!$A:$C,3,FALSE),"") -> CARPINTEIRO
C87: =C86+1 -> 55 | D87: =IFERROR(VLOOKUP($C87,efetivo!$A:$C,2,FALSE),"") -> MARCOS MARCELINO | H87: =IFERROR(VLOOKUP($C87,efetivo!$A:$C,3,FALSE),"") -> CARPINTEIRO
C88: =C87+1 -> 56 | D88: =IFERROR(VLOOKUP($C88,efetivo!$A:$C,2,FALSE),"") -> JOSE CARLOS LIMA PAZ | H88: =IFERROR(VLOOKUP($C88,efetivo!$A:$C,3,FALSE),"") -> CARPINTEIRO
... C118: =C117+1 -> 86 | D118: =IFERROR(VLOOKUP($C118,efetivo!$A:$C,2,FALSE),"") -> ISMAEL VICENTE DE SOUZA | H118: =IFERROR(VLOOKUP($C118,efetivo!$A:$C,3,FALSE),"") -> MOTORISTA DE CAMINHÃO BASCULANTE I
C132: Executante: | D132: CONSÓRCIO RODOVIA PR 317 IGUARAÇU MARINGÁ | J132: Contrato: | K132: 141 / 2025
C133: Rodovia: | D133: PR-317 | J133: Relatório Nº: | K133: 13
C134: Trecho: | D134: DUPLICAÇÃO E RESTAURAÇÃO DA PISTA EXISTENTE DA RODOVIA PR-317, TRECHO IGUARAÇU–MARINGÁ | J134: Período de Referência: | K134: 46235
C136: N.° | D136: Nome | H136: Função
...

Sheet efetivo
A1: 1 | B1: DANIEL DRAGO SANTANA | C1: AJUDANTE GERAL
A2: 2 | B2: GUILHERME BREGUES DOS SANTOS | C2: AJUDANTE GERAL
A3: 3 | B3: LEONE JOAO RAIMUNDO | C3: AJUDANTE GERAL
A4: 4 | B4: ROBENILTON ALVES DOS SANTOS | C4: AJUDANTE GERAL
A5: 5 | B5: RODOLFO LUIZ DA ROCHA | C5: AJUDANTE GERAL
A6: 6 | B6: SIDNEI APARECIDO PEREIRA | C6: AJUDANTE GERAL
A7: 7 | B7: CLEITON MIGUEL DA CUNHA | C7: AJUDANTE GERAL
A8: 8 | B8: JESUINO GERALDO DOS ANJOS | C8: AJUDANTE GERAL
A9: 9 | B9: KAIQUE APARECIDO CUNHA HONORATO | C9: AJUDANTE GERAL
A10: 10 | B10: LEONARDO MOTA | C10: AJUDANTE GERAL
A11: 11 | B11: EVONIO CRISTIANO RODRIGUES FERREIRA | C11: AJUDANTE GERAL
A12: 12 | B12: JANDERSON CESAR PEREIRA ; | C12: AJUDANTE GERAL
... A137: 137 | B137: WANDERSON VIEIRA DA SILVA | C137: RASTELEIRO III

Sheet Equipamentos
C8: Executante: | D8: ='Equipe Técnica Exec.'!D8 -> CONSÓRCIO RODOVIA PR 317 IGUARAÇU MARINGÁ | I8: Contrato: | J8: ='Equipe Técnica Exec.'!K8 -> 141 / 2025
C9: Rodovia: | D9: ='Equipe Técnica Exec.'!D9 -> PR-317 | I9: Relatório N: | J9: ='Equipe Técnica Exec.'!K9 -> 13
C10: Trecho: | D10: ='Equipe Técnica Exec.'!D10 -> DUPLICAÇÃO E RESTAURAÇÃO DA PISTA EXISTENTE DA RODOVIA PR-317, TRECHO IGUARAÇU–MARINGÁ | I10: Período de Referência: | J10: ='Equipe Técnica Exec.'!K10 -> 46235
C12: Equipamentos | G12: Quantidades
G13: Período Anterior | H13: Período Atual | I13: Mobilizado | J13: Desmobilizado
C15: CÓDIGO | D15: DESCRIÇÃO
C16: MN 96 | D16: MOTONIVELADORA | I16: SIM
C17: MN 107 | D17: MOTONIVELADORA | I17: SIM
C18: CP 19 | D18: CAMINHÃO PIPA | I18: SIM
C19: CP 120 | D19: CAMINHÃO PIPA | I19: SIM
C20: RV 25 | D20: ROLO CORRUGADO | I20: SIM
C21: RV 30 | D21: ROLO CHAPA | I21: SIM
C22: RV 57 | D22: ROLO CHAPA | I22: SIM
C23: ES 138 | D23: ESCAVADEIRA | I23: SIM
C24: ES 136 | D24: ESCAVADEIRA | I24: SIM
C25: RP 32 | D25: ROLO PNEU | I25: SIM
C26: RP 26 | D26: ROLO PNEU | I26: SIM
C27: VA 17 | D27: ACABADORA | I27: SIM
... C52: CBM 298 | D52: CAMINHÃO BASCULANTE | I52: SIM

Sheet Ação Corretiva
C8: Executante: | D8: ='Equipe Técnica Exec.'!D8 -> CONSÓRCIO RODOVIA PR 317 IGUARAÇU MARINGÁ | J8: Contrato: | K8: ='Equipe Técnica Exec.'!K8 -> 141 / 2025
C9: Rodovia: | D9: ='Equipe Técnica Exec.'!D9 -> PR-317 | J9: Relatório Nº: | K9: ='Equipe Técnica Exec.'!K9 -> 13
C10: Trecho: | D10: ='Equipe Técnica Exec.'!D10 -> DUPLICAÇÃO E RESTAURAÇÃO DA PISTA EXISTENTE DA RODOVIA PR-317, TRECHO IGUARAÇU–MARINGÁ | J10: Período de Referência: | K10: ='Equipe Técnica Exec.'!K10 -> 46235
C12: N.° - RNF | D12: Ação Corretiva | H12: Habilitação
D13: Implementação | F13: Não Implementada | H13: Sim | J13: Não
C24: QuantidadeTotal de Ação Corretiva
C25: Quantidade Total de Ação Corretiva Implementada
C26: Quantidade Total de Ação Corretiva Eficaz
C28: Comentários:

Sheet Controle Pluv.
C7: Executante: | E7: CONSÓRCIO RODOVIA PR 317 IGUARAÇU MARINGÁ | L7: Contrato | M7: ='Equipe Técnica Exec.'!K8 -> 141 / 2025
C8: Rodovia: | E8: PR-317 | L8: Relatório N: | M8: ='Equipe Técnica Exec.'!K9 -> 13
C9: Trecho: | E9: DUPLICAÇÃO E RESTAURAÇÃO DA PISTA EXISTENTE DA RODOVIA PR-317, TRECHO IGUARAÇU–MARINGÁ | L9: Período de Referência: | M9: ='Equipe Técnica Exec.'!K10 -> 46235
R10: =E12 -> 46235
D12: Mês: | E12: =M9 -> 46235 | K12: COMENTÁRIOS
D13: Dia | F13: Período | I13: Precipitação (mm) | R13: =D13 -> Dia | S13: =I13 -> Precipitação (mm)
F14: Manhã | G14: Tarde | H14: Noite | R14: =D15 -> 46235 | S14: =I15 -> 0
D15: 46235 | E15: =IF(WEEKDAY(D15)=1,"DOM",IF(WEEKDAY(D15)=2,"SEG",IF(WEEKDAY(D15)=3,"TER",IF(WEEKDAY(D15)=4,"QUA",IF(WEEKDAY(D15)=5,"QUI",IF(WEEKDAY(D15)=6,"SEX","SÁB")))))) -> SÁB | F15: 0 | G15: 0 | H15: 0 | I15: =SUM(F15:H15) -> 0 | R15: =D16 -> 46236 | S15: =I16 -> 0
D16: =D15+1 -> 46236 | E16: =IF(WEEKDAY(D16)=1,"DOM",IF(WEEKDAY(D16)=2,"SEG",IF(WEEKDAY(D16)=3,"TER",IF(WEEKDAY(D16)=4,"QUA",IF(WEEKDAY(D16)=5,"QUI",IF(WEEKDAY(D16)=6,"SEX","SÁB")))))) -> DOM | F16: 0 | G16: 0 | H16: 0 | I16: =SUM(F16:H16) -> 0 | K16: Precipitação Total no Período | R16: =D17 -> 46237 | S16: =I17 -> 0
D17: =D16+1 -> 46237 | E17: =IF(WEEKDAY(D17)=1,"DOM",IF(WEEKDAY(D17)=2,"SEG",IF(WEEKDAY(D17)=3,"TER",IF(WEEKDAY(D17)=4,"QUA",IF(WEEKDAY(D17)=5,"QUI",IF(WEEKDAY(D17)=6,"SEX","SÁB")))))) -> SEG | F17: 0 | G17: 0 | H17: 0 | I17: =SUM(F17:H17) -> 0 | R17: =D18 -> 46238 | S17: =I18 -> 0
D18: =D17+1 -> 46238 | E18: =IF(WEEKDAY(D18)=1,"DOM",IF(WEEKDAY(D18)=2,"SEG",IF(WEEKDAY(D18)=3,"TER",IF(WEEKDAY(D18)=4,"QUA",IF(WEEKDAY(D18)=5,"QUI",IF(WEEKDAY(D18)=6,"SEX","SÁB")))))) -> TER | F18: 0 | G18: 0 | H18: 0 | I18: =SUM(F18:H18) -> 0 | K18: =SUM(I15:I46) -> 56.5 | R18: =D19 -> 46239 | S18: =I19 -> 3
D19: =D18+1 -> 46239 | E19: =IF(WEEKDAY(D19)=1,"DOM",IF(WEEKDAY(D19)=2,"SEG",IF(WEEKDAY(D19)=3,"TER",IF(WEEKDAY(D19)=4,"QUA",IF(WEEKDAY(D19)=5,"QUI",IF(WEEKDAY(D19)=6,"SEX","SÁB")))))) -> QUA | F19: 0 | G19: 3 | H19: 0 | I19: =SUM(F19:H19) -> 3 | R19: =D20 -> 46240 | S19: =I20 -> 8.5
D20: =D19+1 -> 46240 | E20: =IF(WEEKDAY(D20)=1,"DOM",IF(WEEKDAY(D20)=2,"SEG",IF(WEEKDAY(D20)=3,"TER",IF(WEEKDAY(D20)=4,"QUA",IF(WEEKDAY(D20)=5,"QUI",IF(WEEKDAY(D20)=6,"SEX","SÁB")))))) -> QUI | F20: 0 | G20: 2.5 | H20: 6 | I20: =SUM(F20:H20) -> 8.5 | R20: =D21 -> 46241 | S20: =I21 -> 10
D21: =D20+1 -> 46241 | E21: =IF(WEEKDAY(D21)=1,"DOM",IF(WEEKDAY(D21)=2,"SEG",IF(WEEKDAY(D21)=3,"TER",IF(WEEKDAY(D21)=4,"QUA",IF(WEEKDAY(D21)=5,"QUI",IF(WEEKDAY(D21)=6,"SEX","SÁB")))))) -> SEX | F21: 3 | G21: 7 | H21: 0 | I21: =SUM(F21:H21) -> 10 | K21: Precipitação Acum. no Período Anterior | R21: =D22 -> 46242 | S21: =I22 -> 0
D22: =D21+1 -> 46242 | E22: =IF(WEEKDAY(D22)=1,"DOM",IF(WEEKDAY(D22)=2,"SEG",IF(WEEKDAY(D22)=3,"TER",IF(WEEKDAY(D22)=4,"QUA",IF(WEEKDAY(D22)=5,"QUI",IF(WEEKDAY(D22)=6,"SEX","SÁB")))))) -> SÁB | F22: 0 | G22: 0 | H22: 0 | I22: =SUM(F22:H22) -> 0 | R22: =D23 -> 46243 | S22: =I23 -> 0
D23: =D22+1 -> 46243 | E23: =IF(WEEKDAY(D23)=1,"DOM",IF(WEEKDAY(D23)=2,"SEG",IF(WEEKDAY(D23)=3,"TER",IF(WEEKDAY(D23)=4,"QUA",IF(WEEKDAY(D23)=5,"QUI",IF(WEEKDAY(D23)=6,"SEX","SÁB")))))) -> DOM | F23: 0 | G23: 0 | H23: 0 | I23: =SUM(F23:H23) -> 0 | K23: =SUM(T52:T62) -> 0 | R23: =D24 -> 46244 | S23: =I24 -> 0
D24: =D23+1 -> 46244 | E24: =IF(WEEKDAY(D24)=1,"DOM",IF(WEEKDAY(D24)=2,"SEG",IF(WEEKDAY(D24)=3,"TER",IF(WEEKDAY(D24)=4,"QUA",IF(WEEKDAY(D24)=5,"QUI",IF(WEEKDAY(D24)=6,"SEX","SÁB")))))) -> SEG | F24: 0 | G24: 0 | H24: 0 | I24: =SUM(F24:H24) -> 0 | R24: =D25 -> 46245 | S24: =I25 -> 0
D25: =D24+1 -> 46245 | E25: =IF(WEEKDAY(D25)=1,"DOM",IF(WEEKDAY(D25)=2,"SEG",IF(WEEKDAY(D25)=3,"TER",IF(WEEKDAY(D25)=4,"QUA",IF(WEEKDAY(D25)=5,"QUI",IF(WEEKDAY(D25)=6,"SEX","SÁB")))))) -> TER | F25: 0 | G25: 0 | H25: 0 | I25: =SUM(F25:H25) -> 0 | R25: =D26 -> 46246 | S25: =I26 -> 0
D26: =D25+1 -> 46246 | E26: =IF(WEEKDAY(D26)=1,"DOM",IF(WEEKDAY(D26)=2,"SEG",IF(WEEKDAY(D26)=3,"TER",IF(WEEKDAY(D26)=4,"QUA",IF(WEEKDAY(D26)=5,"QUI",IF(WEEKDAY(D26)=6,"SEX","SÁB")))))) -> QUA | F26: 0 | G26: 0 | H26: 0 | I26: =SUM(F26:H26) -> 0 | K26: Precipitação Total Acumulada | R26: =D27 -> 46247 | S26: =I27 -> 0
D27: =D26+1 -> 46247 | E27: =IF(WEEKDAY(D27)=1,"DOM",IF(WEEKDAY(D27)=2,"SEG",IF(WEEKDAY(D27)=3,"TER",IF(WEEKDAY(D27)=4,"QUA",IF(WEEKDAY(D27)=5,"QUI",IF(WEEKDAY(D27)=6,"SEX","SÁB")))))) -> QUI | F27: 0 | G27: 0 | H27: 0 | I27: =SUM(F27:H27) -> 0 | R27: =D28 -> 46248 | S27: =I28 -> 0
D28: =D27+1 -> 46248 | E28: =IF(WEEKDAY(D28)=1,"DOM",IF(WEEKDAY(D28)=2,"SEG",IF(WEEKDAY(D28)=3,"TER",IF(WEEKDAY(D28)=4,"QUA",IF(WEEKDAY(D28)=5,"QUI",IF(WEEKDAY(D28)=6,"SEX","SÁB")))))) -> SEX | F28: 0 | G28: 0 | H28: 0 | I28: =SUM(F28:H28) -> 0 | K28: =K23+K18 -> 56.5 | R28: =D29 -> 46249 | S28: =I29 -> 0
D29: =D28+1 -> 46249 | E29: =IF(WEEKDAY(D29)=1,"DOM",IF(WEEKDAY(D29)=2,"SEG",IF(WEEKDAY(D29)=3,"TER",IF(WEEKDAY(D29)=4,"QUA",IF(WEEKDAY(D29)=5,"QUI",IF(WEEKDAY(D29)=6,"SEX","SÁB")))))) -> SÁB | F29: 0 | G29: 0 | H29: 0 | I29: =SUM(F29:H29) -> 0 | R29: =D30 -> 46250 | S29: =I30 -> 0
D30: =D29+1 -> 46250 | E30: =IF(WEEKDAY(D30)=1,"DOM",IF(WEEKDAY(D30)=2,"SEG",IF(WEEKDAY(D30)=3,"TER",IF(WEEKDAY(D30)=4,"QUA",IF(WEEKDAY(D30)=5,"QUI",IF(WEEKDAY(D30)=6,"SEX","SÁB")))))) -> DOM | F30: 0 | G30: 0 | H30: 0 | I30: =SUM(F30:H30) -> 0 | K30: Início da obra: 19/08/2025 | R30: =D31 -> 46251 | S30: =I31 -> 0
D31: =D30+1 -> 46251 | E31: =IF(WEEKDAY(D31)=1,"DOM",IF(WEEKDAY(D31)=2,"SEG",IF(WEEKDAY(D31)=3,"TER",IF(WEEKDAY(D31)=4,"QUA",IF(WEEKDAY(D31)=5,"QUI",IF(WEEKDAY(D31)=6,"SEX","SÁB")))))) -> SEG | F31: 0 | G31: 0 | H31: 0 | I31: =SUM(F31:H31) -> 0 | R31: =D32 -> 46252 | S31: =I32 -> 0
D32: =D31+1 -> 46252 | E32: =IF(WEEKDAY(D32)=1,"DOM",IF(WEEKDAY(D32)=2,"SEG",IF(WEEKDAY(D32)=3,"TER",IF(WEEKDAY(D32)=4,"QUA",IF(WEEKDAY(D32)=5,"QUI",IF(WEEKDAY(D32)=6,"SEX","SÁB")))))) -> TER | F32: 0 | G32: 0 | H32: 0 | I32: =SUM(F32:H32) -> 0 | R32: =D33 -> 46253 | S32: =I33 -> 0
D33: =D32+1 -> 46253 | E33: =IF(WEEKDAY(D33)=1,"DOM",IF(WEEKDAY(D33)=2,"SEG",IF(WEEKDAY(D33)=3,"TER",IF(WEEKDAY(D33)=4,"QUA",IF(WEEKDAY(D33)=5,"QUI",IF(WEEKDAY(D33)=6,"SEX","SÁB")))))) -> QUA | F33: 0 | G33: 0 | H33: 0 | I33: =SUM(F33:H33) -> 0 | R33: =D34 -> 46254 | S33: =I34 -> 0
D34: =D33+1 -> 46254 | E34: =IF(WEEKDAY(D34)=1,"DOM",IF(WEEKDAY(D34)=2,"SEG",IF(WEEKDAY(D34)=3,"TER",IF(WEEKDAY(D34)=4,"QUA",IF(WEEKDAY(D34)=5,"QUI",IF(WEEKDAY(D34)=6,"SEX","SÁB")))))) -> QUI | F34: 0 | G34: 0 | H34: 0 | I34: =SUM(F34:H34) -> 0 | R34: =D35 -> 46255 | S34: =I35 -> 0
D35: =D34+1 -> 46255 | E35: =IF(WEEKDAY(D35)=1,"DOM",IF(WEEKDAY(D35)=2,"SEG",IF(WEEKDAY(D35)=3,"TER",IF(WEEKDAY(D35)=4,"QUA",IF(WEEKDAY(D35)=5,"QUI",IF(WEEKDAY(D35)=6,"SEX","SÁB")))))) -> SEX | F35: 0 | G35: 0 | H35: 0 | I35: =SUM(F35:H35) -> 0 | R35: =D36 -> 46256 | S35: =I36 -> 0
D36: =D35+1 -> 46256 | E36: =IF(WEEKDAY(D36)=1,"DOM",IF(WEEKDAY(D36)=2,"SEG",IF(WEEKDAY(D36)=3,"TER",IF(WEEKDAY(D36)=4,"QUA",IF(WEEKDAY(D36)=5,"QUI",IF(WEEKDAY(D36)=6,"SEX","SÁB")))))) -> SÁB | F36: 0 | G36: 0 | H36: 0 | I36: =SUM(F36:H36) -> 0 | R36: =D37 -> 46257 | S36: =I37 -> 0
D37: =D36+1 -> 46257 | E37: =IF(WEEKDAY(D37)=1,"DOM",IF(WEEKDAY(D37)=2,"SEG",IF(WEEKDAY(D37)=3,"TER",IF(WEEKDAY(D37)=4,"QUA",IF(WEEKDAY(D37)=5,"QUI",IF(WEEKDAY(D37)=6,"SEX","SÁB")))))) -> DOM | F37: 0 | G37: 0 | H37: 0 | I37: =SUM(F37:H37) -> 0 | R37: =D38 -> 46258 | S37: =I38 -> 0
D38: =D37+1 -> 46258 | E38: =IF(WEEKDAY(D38)=1,"DOM",IF(WEEKDAY(D38)=2,"SEG",IF(WEEKDAY(D38)=3,"TER",IF(WEEKDAY(D38)=4,"QUA",IF(WEEKDAY(D38)=5,"QUI",IF(WEEKDAY(D38)=6,"SEX","SÁB")))))) -> SEG | F38: 0 | G38: 0 | H38: 0 | I38: =SUM(F38:H38) -> 0 | R38: =D39 -> 46259 | S38: =I39 -> 5
D39: =D38+1 -> 46259 | E39: =IF(WEEKDAY(D39)=1,"DOM",IF(WEEKDAY(D39)=2,"SEG",IF(WEEKDAY(D39)=3,"TER",IF(WEEKDAY(D39)=4,"QUA",IF(WEEKDAY(D39)=5,"QUI",IF(WEEKDAY(D39)=6,"SEX","SÁB")))))) -> TER | F39: 0 | G39: 0 | H39: 5 | I39: =SUM(F39:H39) -> 5 | R39: =D40 -> 46260 | S39: =I40 -> 0
D40: =D39+1 -> 46260 | E40: =IF(WEEKDAY(D40)=1,"DOM",IF(WEEKDAY(D40)=2,"SEG",IF(WEEKDAY(D40)=3,"TER",IF(WEEKDAY(D40)=4,"QUA",IF(WEEKDAY(D40)=5,"QUI",IF(WEEKDAY(D40)=6,"SEX","SÁB")))))) -> QUA | F40: 0 | G40: 0 | H40: 0 | I40: =SUM(F40:H40) -> 0 | R40: =D41 -> 46261 | S40: =I41 -> 0
D41: =D40+1 -> 46261 | E41: =IF(WEEKDAY(D41)=1,"DOM",IF(WEEKDAY(D41)=2,"SEG",IF(WEEKDAY(D41)=3,"TER",IF(WEEKDAY(D41)=4,"QUA",IF(WEEKDAY(D41)=5,"QUI",IF(WEEKDAY(D41)=6,"SEX","SÁB")))))) -> QUI | F41: 0 | G41: 0 | H41: 0 | I41: =SUM(F41:H41) -> 0 | R41: =D42 -> 46262 | S41: =I42 -> 0
D42: =D41+1 -> 46262 | E42: =IF(WEEKDAY(D42)=1,"DOM",IF(WEEKDAY(D42)=2,"SEG",IF(WEEKDAY(D42)=3,"TER",IF(WEEKDAY(D42)=4,"QUA",IF(WEEKDAY(D42)=5,"QUI",IF(WEEKDAY(D42)=6,"SEX","SÁB")))))) -> SEX | F42: 0 | G42: 0 | H42: 0 | I42: =SUM(F42:H42) -> 0 | R42: =D44 -> 46264 | S42: =I44 -> 0
D43: =D42+1 -> 46263 | E43: =IF(WEEKDAY(D43)=1,"DOM",IF(WEEKDAY(D43)=2,"SEG",IF(WEEKDAY(D43)=3,"TER",IF(WEEKDAY(D43)=4,"QUA",IF(WEEKDAY(D43)=5,"QUI",IF(WEEKDAY(D43)=6,"SEX","SÁB")))))) -> SÁB | F43: 0 | G43: 0 | H43: 0 | I43: 0 | R43: =D45 -> 46265 | S43: =I45 -> 30 | T43: TOTAL
D44: =D43+1 -> 46264 | E44: =IF(WEEKDAY(D44)=1,"DOM",IF(WEEKDAY(D44)=2,"SEG",IF(WEEKDAY(D44)=3,"TER",IF(WEEKDAY(D44)=4,"QUA",IF(WEEKDAY(D44)=5,"QUI",IF(WEEKDAY(D44)=6,"SEX","SÁB")))))) -> DOM | F44: 0 | G44: 0 | H44: 0 | I44: =SUM(F44:H44) -> 0 | T44: =SUM(S14:S43) -> 56.5
D45: =D44+1 -> 46265 | E45: =IF(WEEKDAY(D45)=1,"DOM",IF(WEEKDAY(D45)=2,"SEG",IF(WEEKDAY(D45)=3,"TER",IF(WEEKDAY(D45)=4,"QUA",IF(WEEKDAY(D45)=5,"QUI",IF(WEEKDAY(D45)=6,"SEX","SÁB")))))) -> SEG | F45: 0 | G45: 0 | H45: 30 | I45: =SUM(F45:H45) -> 30
D46: =D45+1 -> 46266 | E46: =IF(WEEKDAY(D46)=1,"DOM",IF(WEEKDAY(D46)=2,"SEG",IF(WEEKDAY(D46)=3,"TER",IF(WEEKDAY(D46)=4,"QUA",IF(WEEKDAY(D46)=5,"QUI",IF(WEEKDAY(D46)=6,"SEX","SÁB")))))) -> TER | F46: 0 | G46: 0 | H46: 0 | I46: =SUM(F46:H46) -> 0
S48: =SUM(S14:S46) -> 56.5 | T48: total mês
...
